1. 问题：通过 `try - catch` 可以自动获取 promise 的 `resolve` 和 `reject` ？    

遇到下面代码，封装了一个函数，如下：   

```js
export default class LsStorage {
  static USER = 0;

  static async getItem(type, key) {
    const res = await AsyncStorage.getItem(`${type.toString()}_${key}`);
    return JSON.parse(res);
  }
}
```

使用时必须放在 `try - catch` 中：   

```js
try {
  const auth = await LsStorage.getItem(LsStorage.USER, 'token');
  headers.append('AccessToken', auth.token);
  headers.append('UserID', auth.uid);
} catch (e) {
  console.log('ajaxerror:', e);
}
```

直接这样使用返回的时 `promise` 对象而不是需要的 `resolve` 的结果

```js
const auth = await LsStorage.getItem(LsStorage.USER, 'token');
console.log(auth); // 返回的时 promise 对象，不是需要的 resolve
```